Workbook

Sheet Vesti 08-25
A1: Fat.2025 | B1: ANIVERSÁRIO | C1: CANAL | D1: MARCA | E1: Subconta | F1: PLANO | G1: SETUP | H1: MENSALIDADE INICIAL | I1: VALOR REAJUSTE | J1: MENSALIDADE | K1: INTEGRAÇÃO | L1: ASSISTENTE | M1: FILIAL | N1: DESCONTOS | O1: TOTAL COBRADO | P1: OBSERVAÇÕES | Q1: Dia Vencimento | R1: Mês de Reajuste | S1: CPFCNPJ
A2: 08/2025 | B2: 42795 | C2: VESTI | D2: TNW Jeans | E2: Vesti (Fatura) | F2: Profissional | H2: 1156 | J2: 1156 | O2: =SUM(J2:M2)-N2 -> 1156 | Q2: 17 | R2: 04 | S2: 4937453000108
A3: 08/2025 | B3: 42937 | C3: Atta | D3: Peonia | E3: Atta | F3: Essencial | H3: 283 | J3: 283 | O3: =SUM(J3:M3)-N3 -> 283 | Q3: 20 | R3: 4 | S3: 07993188000165
A4: 08/2025 | B4: 43160 | C4: Atta | D4: Maria De Chita | E4: Vesti (Fatura) | F4: Profissional | H4: 724 | J4: 724 | O4: =SUM(J4:M4)-N4 -> 724 | Q4: 15 | R4: 04 | S4: 07402979000173
A5: 08/2025 | B5: 43160 | C5: Atta | D5: Shanes | E5: Vesti (Fatura) | F5: Profissional | H5: 1179 | J5: 1179 | O5: =SUM(J5:M5)-N5 -> 1179 | Q5: 20 | R5: 04 | S5: 46446130000153
A6: 08/2025 | B6: 43160 | C6: Atta | D6: Talgui | E6: Vesti (Fatura) | F6: Avançado | H6: 441.33 | J6: 441.33 | O6: =SUM(J6:M6)-N6 -> 441.33 | Q6: 15 | R6: 04 | S6: 05876663000198
A7: 08/2025 | B7: 43160 | C7: Atta | D7: Codi Codi | E7: Vesti (Fatura) | F7: Profissional | H7: 889 | J7: 889 | O7: =SUM(J7:M7)-N7 -> 889 | Q7: 15 | R7: 04 | S7: 18555123000154
A8: 08/2025 | B8: 43160 | C8: Atta | D8: Coinage | E8: Vesti (Fatura) | F8: Profissional | H8: 1179 | J8: 1179 | O8: =SUM(J8:M8)-N8 -> 1179 | Q8: 20 | R8: 04 | S8: 33724927000123
A9: 08/2025 | B9: 43160 | C9: Atta | D9: Moda Inn | E9: Vesti (Fatura) | F9: Essencial | H9: 283 | J9: 283 | O9: =SUM(J9:M9)-N9 -> 283 | Q9: 20 | R9: 04 | S9: 49921554000110
A10: 08/2025 | B10: 43160 | C10: Atta | D10: Licommo | E10: Vesti (Fatura) | F10: Avançado | H10: 425 | J10: 425 | O10: =SUM(J10:M10)-N10 -> 425 | Q10: 15 | R10: 04 | S10: 08325746000187
A11: 08/2025 | B11: 43160 | C11: Atta | D11: Betsey | E11: Vesti (Fatura) | F11: Profissional | H11: 1003 | J11: 1003 | O11: =SUM(J11:M11)-N11 -> 1003 | Q11: 15 | R11: 04 | S11: 06161024000109
A12: 08/2025 | B12: 43160 | C12: Atta | D12: Cashier | E12: Vesti (Fatura) | F12: Profissional | H12: 1015 | J12: 1015 | O12: =SUM(J12:M12)-N12 -> 1015 | Q12: 30 | R12: 04 | S12: 60368669000162
A13: 08/2025 | B13: 43160 | C13: Atta | D13: Cony Green | E13: Vesti (Fatura) | F13: Avançado | H13: 425 | J13: 425 | O13: =SUM(J13:M13)-N13 -> 425 | Q13: 15 | R13: 04 | S13: 44511277000154
A14: 08/2025 | B14: 43160 | C14: Atta | D14: Pury | E14: Vesti (Fatura) | F14: Profissional | H14: 1327 | J14: 1327 | M14: 359 | O14: =SUM(J14:M14)-N14 -> 1686 | Q14: 15 | R14: 04 | S14: 12576594000162
A15: 08/2025 | B15: 43160 | C15: Atta | D15: Nanaminze | E15: Vesti (Fatura) | F15: Profissional | H15: 1179 | J15: 1179 | M15: 359 | O15: =SUM(J15:M15)-N15 -> 1538 | Q15: 15 | R15: 04 | S15: 12656331000163
A16: 08/2025 | B16: 43160 | C16: VESTI | D16: Tricomix | E16: Vesti (Fatura) | F16: Avançado | H16: 1193 | J16: 1193 | K16: 350 | O16: =SUM(J16:M16)-N16 -> 1543 | Q16: 11 | R16: 04 | S16: 04665515000161
A17: 08/2025 | B17: 43160 | C17: Atta | D17: Lov It | E17: Vesti (Fatura) | F17: Avançado | H17: 425 | J17: 425 | O17: =SUM(J17:M17)-N17 -> 425 | Q17: 11 | R17: 04 | S17: 21749422000215
A18: 08/2025 | B18: 43160 | C18: Atta | D18: Hemix | E18: Vesti (Fatura) | F18: Essencial | H18: 283 | J18: 283 | L18: =550+120 -> 670 | O18: =SUM(J18:M18)-N18 -> 953 | Q18: 15 | R18: 04 | S18: 07389520000187
A19: 08/2025 | B19: 43160 | C19: Miredata | D19: Mottive | E19: Vesti (Fatura) | F19: Profissional | H19: 1179 | J19: 1179 | O19: =SUM(J19:M19)-N19 -> 1179 | Q19: 20 | R19: 04 | S19: 24330475000104
A20: 08/2025 | B20: 43160 | C20: Atta | D20: Miss Alfa | E20: Vesti (Fatura) | F20: Essencial | H20: 283 | J20: 283 | O20: =SUM(J20:M20)-N20 -> 283 | Q20: 15 | R20: 04 | S20: 28497561000167
A21: 08/2025 | B21: 43160 | C21: VESTI | D21: Anemone | E21: Vesti (Fatura) | F21: Avançado | H21: 1013 | J21: 1013 | O21: =SUM(J21:M21)-N21 -> 1013 | Q21: 11 | R21: 04 | S21: 30962814000178
A22: 08/2025 | B22: 43160 | C22: Miredata | D22: Pianeta | E22: Vesti (Fatura) | F22: Profissional | H22: 761 | J22: 761 | O22: =SUM(J22:M22)-N22 -> 761 | Q22: 20 | R22: 04 | S22: 31583000000195
A23: 08/2025 | B23: 43356 | C23: Atta | D23: Morina | E23: Vesti (Fatura) | F23: Profissional | H23: 1138 | J23: 1138 | O23: =SUM(J23:M23)-N23 -> 1138 | Q23: 15 | R23: 04 | S23: 44029041000186
A24: 08/2025 | B24: 43586 | C24: Atta | D24: Artemiss | E24: Vesti (Fatura) | F24: Avançado | H24: 569 | J24: 569 | M24: 275 | O24: =SUM(J24:M24)-N24 -> 844 | Q24: 11 | R24: 04 | S24: 05320347000135
A25: 08/2025 | B25: 43586 | C25: Atta | D25: IT LOOK | E25: Vesti (Fatura) | F25: Essencial | H25: 283 | J25: 283 | O25: =SUM(J25:M25)-N25 -> 283 | Q25: 15 | R25: 04 | S25: 21659326000103
A26: 08/2025 | B26: 43586 | C26: Atta | D26: E YUNIRE | E26: Vesti (Fatura) | F26: Essencial | H26: 354 | J26: 354 | O26: =SUM(J26:M26)-N26 -> 354 | Q26: 15 | R26: 04 | S26: 45375658000116
A27: 08/2025 | B27: 43593 | C27: Atta | D27: Incentive | E27: Vesti (Fatura) | F27: Essencial | H27: 528.33 | J27: 528.33 | L27: 850 | O27: =SUM(J27:M27)-N27 -> 1378.33 | Q27: 30 | R27: 04 | S27: 29780242000127
A28: 08/2025 | B28: 43593 | C28: Atta | D28: Mariá/Aurora | E28: Vesti (Fatura) | F28: Essencial | H28: 283 | J28: 283 | O28: =SUM(J28:M28)-N28 -> 283 | Q28: 20 | R28: 04 | S28: 33076814000169
A29: 08/2025 | B29: 43593 | C29: Atta | D29: Mazarin | E29: Vesti (Fatura) | F29: Essencial | H29: 326.67 | J29: 326.67 | O29: =SUM(J29:M29)-N29 -> 326.67 | Q29: 15 | R29: 04 | S29: 03598605000203
A30: 08/2025 | B30: 43600 | C30: Atta | D30: Blue Blossom | E30: Vesti (Fatura) | F30: Essencial | H30: 283 | J30: 283 | O30: =SUM(J30:M30)-N30 -> 283 | Q30: 15 | R30: 04 | S30: 30828978000107
A31: 08/2025 | B31: 43600 | C31: Atta | D31: Dolps | E31: Vesti (Fatura) | F31: Profissional | H31: 1269 | J31: 1269 | O31: =SUM(J31:M31)-N31 -> 1269 | Q31: 15 | R31: 05 | S31: 01802508000176
A32: 08/2025 | B32: 43606 | C32: VESTI | D32: Crocker | E32: Vesti (Fatura) | F32: Profissional | H32: 1179 | J32: 1179 | M32: 410 | O32: =SUM(J32:M32)-N32 -> 1589 | Q32: 15 | R32: 04 | S32: 60652948000153
A33: 08/2025 | B33: 43606 | C33: VESTI | D33: Lesto | E33: Vesti (Fatura) | F33: Essencial | H33: 284.33 | J33: 284.33 | O33: =SUM(J33:M33)-N33 -> 284.33 | Q33: 15 | R33: 04 | S33: 58418377000145
A34: 08/2025 | B34: 43619 | C34: Atta | D34: Ellen One | E34: Vesti (Cartão) | F34: Essencial | H34: 283 | J34: 283 | O34: =SUM(J34:M34)-N34 -> 283 | Q34: 06 | R34: 4 | S34: 07554437000116
A35: 08/2025 | B35: 43619 | C35: Atta | D35: Instar | E35: Vesti (Fatura) | F35: Essencial | H35: 283 | J35: 283 | O35: =SUM(J35:M35)-N35 -> 283 | Q35: 15 | R35: 04 | S35: 32649954000116
A36: 08/2025 | B36: 43633 | C36: Atta | D36: Aramodu | E36: Vesti (Fatura) | F36: Essencial | H36: 283 | J36: 283 | O36: =SUM(J36:M36)-N36 -> 283 | Q36: 11 | R36: 04 | S36: 97541061000106
A37: 08/2025 | B37: 43643 | C37: Atta | D37: Scera | E37: Vesti (Fatura) | F37: Essencial | H37: 283 | J37: 283 | O37: =SUM(J37:M37)-N37 -> 283 | Q37: 15 | R37: 04 | S37: 23333642000108
A38: 08/2025 | B38: 43649 | C38: Atta | D38: Fama Fashion | E38: Vesti (Fatura) | F38: Essencial | H38: 283 | J38: 283 | O38: =SUM(J38:M38)-N38 -> 283 | Q38: 20 | R38: 04 | S38: 54451398000101
A39: 08/2025 | B39: 43649 | C39: VESTI | D39: Paloma Concept | E39: Vesti (Fatura) | F39: Essencial | H39: 283 | J39: 283 | O39: =SUM(J39:M39)-N39 -> 283 | Q39: 15 | R39: 04 | S39: 16579598000155
A40: 08/2025 | B40: 43656 | C40: Atta | D40: Cheers | E40: Vesti (Fatura) | F40: Profissional | H40: 1179 | J40: 1179 | O40: =SUM(J40:M40)-N40 -> 1179 | Q40: 11 | R40: 04 | S40: 53659785000175
...

Sheet Vesti 09-25
A1: Fat.2025 | B1: ANIVERSÁRIO | C1: CANAL | D1: MARCA | E1: Subconta | F1: PLANO | G1: SETUP | H1: MENSALIDADE INICIAL | I1: VALOR REAJUSTE | J1: MENSALIDADE | K1: INTEGRAÇÃO | L1: ASSISTENTE | M1: FILIAL | N1: DESCONTOS | O1: TOTAL COBRADO | P1: OBSERVAÇÕES | Q1: Dia Vencimento | R1: Mês de Reajuste | S1: CPFCNPJ
A2: 09/2025 | B2: 42795 | C2: VESTI | D2: TNW Jeans | E2: Vesti (Assinatura) | F2: Profissional | H2: 1156 | J2: 1156 | O2: =SUM(J2:M2)-N2 -> 1156 | Q2: 17 | R2: 04 | S2: 4937453000108
A3: 09/2025 | B3: 42937 | C3: Atta | D3: Peonia | E3: Atta | F3: Essencial | H3: 302 | J3: 302 | O3: =SUM(J3:M3)-N3 -> 302 | Q3: 20 | R3: 4 | S3: 07993188000165
A4: 09/2025 | B4: 43160 | C4: Atta | D4: Maria De Chita | E4: Vesti (Assinatura) | F4: Profissional | H4: 724 | J4: 724 | O4: =SUM(J4:M4)-N4 -> 724 | Q4: 15 | R4: 04 | S4: 07402979000173
A5: 09/2025 | B5: 43160 | C5: Atta | D5: Shanes | E5: Vesti (Assinatura) | F5: Profissional | H5: 1179 | J5: 1179 | O5: =SUM(J5:M5)-N5 -> 1179 | Q5: 20 | R5: 04 | S5: 46446130000153
A6: 09/2025 | B6: 43160 | C6: Atta | D6: Talgui | E6: Vesti (Assinatura) | F6: Avançado | H6: 441.33 | J6: 441.33 | O6: =SUM(J6:M6)-N6 -> 441.33 | Q6: 15 | R6: 04 | S6: 05876663000198
A7: 09/2025 | B7: 43160 | C7: Atta | D7: Codi Codi | E7: Vesti (Assinatura) | F7: Profissional | H7: 889 | J7: 889 | O7: =SUM(J7:M7)-N7 -> 889 | Q7: 15 | R7: 04 | S7: 18555123000154
A8: 09/2025 | B8: 43160 | C8: Atta | D8: Coinage | E8: Vesti (Assinatura) | F8: Profissional | H8: 1179 | J8: 1179 | O8: =SUM(J8:M8)-N8 -> 1179 | Q8: 20 | R8: 04 | S8: 33724927000123
A9: 09/2025 | B9: 43160 | C9: Atta | D9: Moda Inn | E9: Vesti (Assinatura) | F9: Essencial | H9: 283 | J9: 283 | O9: =SUM(J9:M9)-N9 -> 283 | Q9: 20 | R9: 04 | S9: 49921554000110
A10: 09/2025 | B10: 43160 | C10: Atta | D10: Licommo | E10: Vesti (Assinatura) | F10: Avançado | H10: 425 | J10: 425 | O10: =SUM(J10:M10)-N10 -> 425 | Q10: 15 | R10: 04 | S10: 08325746000187
A11: 09/2025 | B11: 43160 | C11: Atta | D11: Betsey | E11: Vesti (Assinatura) | F11: Profissional | H11: 1003 | J11: 1003 | O11: =SUM(J11:M11)-N11 -> 1003 | Q11: 15 | R11: 04 | S11: 06161024000109
A12: 09/2025 | B12: 43160 | C12: Atta | D12: Cashier | E12: Vesti (Assinatura) | F12: Profissional | H12: 1015 | J12: 1015 | O12: =SUM(J12:M12)-N12 -> 1015 | Q12: 30 | R12: 04 | S12: 60368669000162
A13: 09/2025 | B13: 43160 | C13: Atta | D13: Cony Green | E13: Vesti (Assinatura) | F13: Avançado | H13: 425 | J13: 425 | O13: =SUM(J13:M13)-N13 -> 425 | Q13: 15 | R13: 04 | S13: 44511277000154
A14: 09/2025 | B14: 43160 | C14: Atta | D14: Pury | E14: Vesti (Assinatura) | F14: Profissional | H14: 1327 | J14: 1327 | M14: 359 | O14: =SUM(J14:M14)-N14 -> 1686 | Q14: 15 | R14: 04 | S14: 12576594000162
A15: 09/2025 | B15: 43160 | C15: Atta | D15: Nanaminze | E15: Vesti (Assinatura) | F15: Profissional | H15: 1179 | J15: 1179 | M15: 359 | O15: =SUM(J15:M15)-N15 -> 1538 | Q15: 15 | R15: 04 | S15: 12656331000163
A16: 09/2025 | B16: 43160 | C16: VESTI | D16: Tricomix | E16: Vesti (Assinatura) | F16: Avançado | H16: 1193 | J16: 1193 | K16: 350 | O16: =SUM(J16:M16)-N16 -> 1543 | Q16: 11 | R16: 04 | S16: 04665515000161
A17: 09/2025 | B17: 43160 | C17: Atta | D17: Lov It | E17: Vesti (Assinatura) | F17: Avançado | H17: 425 | J17: 425 | O17: =SUM(J17:M17)-N17 -> 425 | Q17: 11 | R17: 04 | S17: 21749422000215
A18: 09/2025 | B18: 43160 | C18: Atta | D18: Hemix | E18: Vesti (Assinatura) | F18: Essencial | H18: 283 | J18: 283 | L18: =550+120 -> 670 | O18: =SUM(J18:M18)-N18 -> 953 | Q18: 15 | R18: 04 | S18: 07389520000187
A19: 09/2025 | B19: 43160 | C19: Miredata | D19: Mottive | E19: Vesti (Assinatura) | F19: Profissional | H19: 1179 | J19: 1179 | O19: =SUM(J19:M19)-N19 -> 1179 | Q19: 20 | R19: 04 | S19: 24330475000104
A20: 09/2025 | B20: 43160 | C20: Atta | D20: Miss Alfa | E20: Vesti (Assinatura) | F20: Essencial | H20: 283 | J20: 283 | O20: =SUM(J20:M20)-N20 -> 283 | Q20: 15 | R20: 04 | S20: 28497561000167
A21: 09/2025 | B21: 43160 | C21: VESTI | D21: Anemone | E21: Vesti (Assinatura) | F21: Avançado | H21: 1013 | J21: 1013 | O21: =SUM(J21:M21)-N21 -> 1013 | Q21: 11 | R21: 04 | S21: 30962814000178
A22: 09/2025 | B22: 43160 | C22: Miredata | D22: Pianeta | E22: Vesti (Assinatura) | F22: Profissional | H22: 761 | J22: 761 | O22: =SUM(J22:M22)-N22 -> 761 | Q22: 20 | R22: 04 | S22: 31583000000195
A23: 09/2025 | B23: 43356 | C23: Atta | D23: Morina | E23: Vesti (Assinatura) | F23: Profissional | H23: 1138 | J23: 1138 | O23: =SUM(J23:M23)-N23 -> 1138 | Q23: 15 | R23: 04 | S23: 44029041000186
A24: 09/2025 | B24: 43586 | C24: Atta | D24: Artemiss | E24: Vesti (Assinatura) | F24: Avançado | H24: 569 | J24: 569 | M24: 275 | O24: =SUM(J24:M24)-N24 -> 844 | Q24: 11 | R24: 04 | S24: 05320347000135
A25: 09/2025 | B25: 43586 | C25: Atta | D25: IT LOOK | E25: Vesti (Assinatura) | F25: Essencial | H25: 283 | J25: 283 | O25: =SUM(J25:M25)-N25 -> 283 | Q25: 15 | R25: 04 | S25: 21659326000103
A26: 09/2025 | B26: 43586 | C26: Atta | D26: E YUNIRE | E26: Vesti (Assinatura) | F26: Essencial | H26: 354 | J26: 354 | O26: =SUM(J26:M26)-N26 -> 354 | Q26: 15 | R26: 04 | S26: 45375658000116
A27: 09/2025 | B27: 43593 | C27: Atta | D27: Incentive | E27: Vesti (Assinatura) | F27: Essencial | H27: 528.33 | J27: 528.33 | L27: 850 | O27: =SUM(J27:M27)-N27 -> 1378.33 | Q27: 30 | R27: 04 | S27: 29780242000127
A28: 09/2025 | B28: 43593 | C28: Atta | D28: Mariá/Aurora | E28: Vesti (Assinatura) | F28: Essencial | H28: 283 | J28: 283 | O28: =SUM(J28:M28)-N28 -> 283 | Q28: 20 | R28: 04 | S28: 33076814000169
A29: 09/2025 | B29: 43593 | C29: Atta | D29: Mazarin | E29: Vesti (Assinatura) | F29: Essencial | H29: 326.67 | J29: 326.67 | O29: =SUM(J29:M29)-N29 -> 326.67 | Q29: 15 | R29: 04 | S29: 03598605000203
A30: 09/2025 | B30: 43600 | C30: Atta | D30: Blue Blossom | E30: Vesti (Assinatura) | F30: Essencial | H30: 283 | J30: 283 | M30: 410 | O30: =SUM(J30:M30)-N30 -> 693 | Q30: 15 | R30: 04 | S30: 30828978000107
A31: 09/2025 | B31: 43606 | C31: VESTI | D31: Crocker | E31: Vesti (Assinatura) | F31: Profissional | H31: 1179 | J31: 1179 | M31: 410 | O31: =SUM(J31:M31)-N31 -> 1589 | Q31: 15 | R31: 04 | S31: 60652948000153
A32: 09/2025 | B32: 43606 | C32: VESTI | D32: Lesto | E32: Vesti (Assinatura) | F32: Essencial | H32: 284.33 | J32: 284.33 | O32: =SUM(J32:M32)-N32 -> 284.33 | Q32: 15 | R32: 04 | S32: 58418377000145
A33: 09/2025 | B33: 43619 | C33: Atta | D33: Ellen One | E33: Vesti (Cartão) | F33: Essencial | H33: 283 | J33: 283 | O33: =SUM(J33:M33)-N33 -> 283 | Q33: 06 | R33: 4 | S33: 07554437000116
A34: 09/2025 | B34: 43619 | C34: Atta | D34: Instar | E34: Vesti (Assinatura) | F34: Essencial | H34: 283 | J34: 283 | O34: =SUM(J34:M34)-N34 -> 283 | Q34: 15 | R34: 04 | S34: 32649954000116
A35: 09/2025 | B35: 43633 | C35: Atta | D35: Aramodu | E35: Vesti (Assinatura) | F35: Essencial | H35: 283 | J35: 283 | O35: =SUM(J35:M35)-N35 -> 283 | Q35: 11 | R35: 04 | S35: 97541061000106
A36: 09/2025 | B36: 43643 | C36: Atta | D36: Scera | E36: Vesti (Assinatura) | F36: Essencial | H36: 283 | J36: 283 | M36: 410 | O36: =SUM(J36:M36)-N36 -> 693 | Q36: 15 | R36: 04 | S36: 23333642000108
A37: 09/2025 | B37: 43649 | C37: Atta | D37: Fama Fashion | E37: Vesti (Assinatura) | F37: Essencial | H37: 283 | J37: 283 | O37: =SUM(J37:M37)-N37 -> 283 | Q37: 20 | R37: 04 | S37: 54451398000101
A38: 09/2025 | B38: 43649 | C38: VESTI | D38: Paloma Concept | E38: Vesti (Assinatura) | F38: Essencial | H38: 283 | J38: 283 | O38: =SUM(J38:M38)-N38 -> 283 | Q38: 15 | R38: 04 | S38: 16579598000155
A39: 09/2025 | B39: 43656 | C39: Atta | D39: Cheers | E39: Vesti (Assinatura) | F39: Profissional | H39: 1179 | J39: 1179 | O39: =SUM(J39:M39)-N39 -> 1179 | Q39: 11 | R39: 04 | S39: 53659785000175
A40: 09/2025 | B40: 43656 | C40: Atta | D40: Fesperamor | E40: Vesti (Assinatura) | F40: Profissional | H40: 1179 | J40: 1179 | O40: =SUM(J40:M40)-N40 -> 1179 | Q40: 15 | R40: 04 | S40: 22015485000120
...

Sheet Vesti 10-25
A1: Fat.2025 | B1: ANIVERSÁRIO | C1: CANAL | D1: MARCA | E1: Subconta | F1: PLANO | G1: SETUP | H1: MENSALIDADE INICIAL | I1: VALOR REAJUSTE | J1: MENSALIDADE | K1: INTEGRAÇÃO | L1: ASSISTENTE | M1: FILIAL | N1: DESCONTOS | O1: TOTAL COBRADO | P1: OBSERVAÇÕES | Q1: Dia Vencimento | R1: Mês de Reajuste | S1: CPFCNPJ | T1: NOME/RAZÃO SOCIAL
A2: 10/2025 | B2: 42795 | C2: VESTI | D2: TNW Jeans | E2: Vesti (Assinatura) | F2: Profissional | H2: 1156 | J2: 1156 | O2: =SUM(J2:M2)-N2 -> 1156 | Q2: 17 | R2: 04 | S2: 4937453000108 | T2: TNW JEANS = TNW CONFECCOES LTDA
A3: 10/2025 | B3: 42937 | C3: Atta | D3: Peonia | E3: Atta | F3: Essencial | H3: 302 | J3: 302 | O3: =SUM(J3:M3)-N3 -> 302 | Q3: 20 | R3: 4 | S3: 07993188000165
A4: 10/2025 | B4: 43160 | C4: Atta | D4: Maria De Chita | E4: Vesti (Assinatura) | F4: Profissional | H4: 724 | J4: 724 | O4: =SUM(J4:M4)-N4 -> 724 | Q4: 15 | R4: 04 | S4: 07402979000173 | T4: MARIA DE CHITA = MARIA DE CHITA CONFECCOES LTDA
A5: 10/2025 | B5: 43160 | C5: Atta | D5: Shanes | E5: Vesti (Assinatura) | F5: Profissional | H5: 1179 | J5: 1179 | O5: =SUM(J5:M5)-N5 -> 1179 | Q5: 20 | R5: 04 | S5: 46446130000153 | T5: SHANES = CONFECCOES SHANES LTDA
A6: 10/2025 | B6: 43160 | C6: Atta | D6: Talgui | E6: Vesti (Assinatura) | F6: Avançado | H6: 441.33 | J6: 441.33 | O6: =SUM(J6:M6)-N6 -> 441.33 | Q6: 15 | R6: 04 | S6: 05876663000198 | T6: TALGUI = TALGUI CONFECCOES DE ROUPAS LTDA
A7: 10/2025 | B7: 43160 | C7: Atta | D7: Codi Codi | E7: Vesti (Assinatura) | F7: Profissional | H7: 889 | J7: 889 | O7: =SUM(J7:M7)-N7 -> 889 | Q7: 15 | R7: 04 | S7: 18555123000154 | T7: CODI CODI = MOONKA CONFECCOES LTDA EPP
A8: 10/2025 | B8: 43160 | C8: Atta | D8: Coinage | E8: Vesti (Assinatura) | F8: Profissional | H8: 1179 | J8: 1179 | O8: =SUM(J8:M8)-N8 -> 1179 | Q8: 20 | R8: 04 | S8: 33724927000123 | T8: Coinage = DON IN CONFECCOES LTDA
A9: 10/2025 | B9: 43160 | C9: Atta | D9: Moda Inn | E9: Vesti (Assinatura) | F9: Essencial | H9: 283 | J9: 283 | O9: =SUM(J9:M9)-N9 -> 283 | Q9: 20 | R9: 04 | S9: 49921554000110 | T9: MODA INN = CONFECCOES SIMON LTDA
A10: 10/2025 | B10: 43160 | C10: Atta | D10: Licommo | E10: Vesti (Assinatura) | F10: Avançado | H10: 425 | J10: 425 | O10: =SUM(J10:M10)-N10 -> 425 | Q10: 15 | R10: 04 | S10: 08325746000187 | T10: LICOMMO = CONFECCOES LICOMMO LTDA
A11: 10/2025 | B11: 43160 | C11: Atta | D11: Betsey | E11: Vesti (Assinatura) | F11: Profissional | H11: 1003 | J11: 1003 | O11: =SUM(J11:M11)-N11 -> 1003 | Q11: 15 | R11: 04 | S11: 06161024000109 | T11: BETSEY = BETSEY CONFECCOES LTDA
A12: 10/2025 | B12: 43160 | C12: Atta | D12: Cashier | E12: Vesti (Assinatura) | F12: Profissional | H12: 1015 | J12: 1015 | O12: =SUM(J12:M12)-N12 -> 1015 | Q12: 30 | R12: 04 | S12: 60368669000162 | T12: CASHIER = CASHIER CONFECCOES LTDA
A13: 10/2025 | B13: 43160 | C13: Atta | D13: Cony Green | E13: Vesti (Assinatura) | F13: Avançado | H13: 425 | J13: 425 | O13: =SUM(J13:M13)-N13 -> 425 | Q13: 15 | R13: 04 | S13: 44511277000154 | T13: CONY GREEN = CONFECCOES E MODAS CONY GREEN LTDA
A14: 10/2025 | B14: 43160 | C14: Atta | D14: Pury | E14: Vesti (Assinatura) | F14: Profissional | H14: 1327 | J14: 1327 | M14: 359 | O14: =SUM(J14:M14)-N14 -> 1686 | Q14: 15 | R14: 04 | S14: 12576594000162 | T14: PURY = CONFECCOES PURY LTDA
A15: 10/2025 | B15: 43160 | C15: Atta | D15: Nanaminze | E15: Vesti (Assinatura) | F15: Profissional | H15: 1179 | J15: 1179 | M15: 359 | O15: =SUM(J15:M15)-N15 -> 1538 | Q15: 15 | R15: 04 | S15: 12656331000163 | T15: NANAMINZE = HELIAS DAI KIM
A16: 10/2025 | B16: 43160 | C16: VESTI | D16: Tricomix | E16: Vesti (Assinatura) | F16: Avançado | H16: 1193 | J16: 1193 | K16: 350 | O16: =SUM(J16:M16)-N16 -> 1543 | Q16: 11 | R16: 04 | S16: 04665515000161 | T16: TRICOMIX = TRICOMIX INDUSTRIA E COMERCIO DE CONFECCOES EIRELI
A17: 10/2025 | B17: 43160 | C17: Atta | D17: Lov It | E17: Vesti (Assinatura) | F17: Avançado | H17: 425 | J17: 425 | O17: =SUM(J17:M17)-N17 -> 425 | Q17: 11 | R17: 04 | S17: 21749422000215 | T17: LOV IT = WELOVIT CONFECCOES LTDA
A18: 10/2025 | B18: 43160 | C18: Atta | D18: Hemix | E18: Vesti (Assinatura) | F18: Essencial | H18: 283 | J18: 283 | L18: =550+120 -> 670 | O18: =SUM(J18:M18)-N18 -> 953 | Q18: 15 | R18: 04 | S18: 07389520000187 | T18: HEMIX = HEMIX CONFECCOES LTDA
A19: 10/2025 | B19: 43160 | C19: Miredata | D19: Mottive | E19: Vesti (Assinatura) | F19: Profissional | H19: 1179 | J19: 1179 | O19: =SUM(J19:M19)-N19 -> 1179 | Q19: 20 | R19: 04 | S19: 24330475000104 | T19: MOTTIVE = PROBELLAS CONFECCOES LTDA EPP
A20: 10/2025 | B20: 43160 | C20: Atta | D20: Miss Alfa | E20: Vesti (Assinatura) | F20: Essencial | H20: 283 | J20: 283 | O20: =SUM(J20:M20)-N20 -> 283 | Q20: 15 | R20: 04 | S20: 28497561000167 | T20: MISS ALFA = MISS ALFA COMERCIO DE ROUPAS LTDA
A21: 10/2025 | B21: 43160 | C21: VESTI | D21: Anemone | E21: Vesti (Assinatura) | F21: Avançado | H21: 1013 | J21: 1013 | O21: =SUM(J21:M21)-N21 -> 1013 | Q21: 11 | R21: 04 | S21: 30962814000178 | T21: ANEMONE = MM21 INDUSTRIA E COMERCIO DE ROUPAS LTDA
A22: 10/2025 | B22: 43160 | C22: Miredata | D22: Pianeta | E22: Vesti (Assinatura) | F22: Profissional | H22: 761 | J22: 761 | O22: =SUM(J22:M22)-N22 -> 761 | Q22: 20 | R22: 04 | S22: 31583000000195 | T22: PIANETA = INTERMIX CONFECCOES DE ROUPAS LTDA
A23: 10/2025 | B23: 43356 | C23: Atta | D23: Morina | E23: Vesti (Assinatura) | F23: Profissional | H23: 1138 | J23: 1138 | O23: =SUM(J23:M23)-N23 -> 1138 | Q23: 15 | R23: 04 | S23: 44029041000186 | T23: Morina = FYK CONFECCOES LTDA
A24: 10/2025 | B24: 43586 | C24: Atta | D24: Artemiss | E24: Vesti (Assinatura) | F24: Avançado | H24: 569 | J24: 569 | M24: 275 | O24: =SUM(J24:M24)-N24 -> 844 | Q24: 11 | R24: 04 | S24: 05320347000135 | T24: ARTEMISS = CONFECCOES ARTE E MISS LTDA
A25: 10/2025 | B25: 43586 | C25: Atta | D25: IT LOOK | E25: Vesti (Assinatura) | F25: Essencial | H25: 283 | J25: 283 | O25: =SUM(J25:M25)-N25 -> 283 | Q25: 15 | R25: 04 | S25: 21659326000103 | T25: IT LOOK = IT LOOK CONFECCAO E COMERCIO DE ROUPAS LTDA
A26: 10/2025 | B26: 43586 | C26: Atta | D26: E YUNIRE | E26: Vesti (Assinatura) | F26: Essencial | H26: 354 | J26: 354 | O26: =SUM(J26:M26)-N26 -> 354 | Q26: 15 | R26: 04 | S26: 45375658000116 | T26: E YUNIRE = YUNIVEST CONFECCOES LTDA
A27: 10/2025 | B27: 43593 | C27: Atta | D27: Incentive | E27: Vesti (Assinatura) | F27: Essencial | H27: 528.33 | J27: 528.33 | L27: 850 | O27: =SUM(J27:M27)-N27 -> 1378.33 | Q27: 30 | R27: 04 | S27: 29780242000127 | T27: INCENTIVE = CONFECCOES INCENTIVE LTDA
A28: 10/2025 | B28: 43593 | C28: Atta | D28: Mariá/Aurora | E28: Vesti (Assinatura) | F28: Essencial | H28: 283 | J28: 283 | O28: =SUM(J28:M28)-N28 -> 283 | Q28: 20 | R28: 04 | S28: 33076814000169 | T28: Maria/Aurora = OK MI DO
A29: 10/2025 | B29: 43593 | C29: Atta | D29: Mazarin | E29: Vesti (Assinatura) | F29: Essencial | H29: 326.67 | J29: 326.67 | O29: =SUM(J29:M29)-N29 -> 326.67 | Q29: 15 | R29: 04 | S29: 03598605000203 | T29: MAZARIN = CONFECCOES MAZARIN LTDA
A30: 10/2025 | B30: 43600 | C30: Atta | D30: Blue Blossom | E30: Vesti (Assinatura) | F30: Essencial | H30: 283 | J30: 283 | M30: 410 | O30: =SUM(J30:M30)-N30 -> 693 | Q30: 15 | R30: 04 | S30: 30828978000107 | T30: BLUE BLOSSOM = BLUE BLOSSOM CONFECCOES EIRELI
A31: 10/2025 | B31: 43606 | C31: VESTI | D31: Crocker | E31: Vesti (Assinatura) | F31: Profissional | H31: 1179 | J31: 1179 | M31: 410 | O31: =SUM(J31:M31)-N31 -> 1589 | Q31: 15 | R31: 04 | S31: 60652948000153 | T31: CROCKER = US BRASIL INDUSTRIA E COMERCIO DE ROUPAS LTDA
A32: 10/2025 | B32: 43606 | C32: VESTI | D32: Lesto | E32: Vesti (Assinatura) | F32: Essencial | H32: 284.33 | J32: 284.33 | O32: =SUM(J32:M32)-N32 -> 284.33 | Q32: 15 | R32: 04 | S32: 58418377000145 | T32: LESTO = LESTO CONFECCOES LTDA
A33: 10/2025 | B33: 43619 | C33: Atta | D33: Ellen One | E33: Vesti (Cartão) | F33: Essencial | H33: 283 | J33: 283 | O33: =SUM(J33:M33)-N33 -> 283 | Q33: 06 | R33: 4 | S33: 07554437000116 | T33: Ellen One = CONFECCOES ELLEN ONE EIRELI
A34: 10/2025 | B34: 43619 | C34: Atta | D34: Instar | E34: Vesti (Assinatura) | F34: Essencial | H34: 283 | J34: 283 | O34: =SUM(J34:M34)-N34 -> 283 | Q34: 15 | R34: 04 | S34: 32649954000116 | T34: INSTAR = CLASSY MISSY CONFECCAO DE ROUPAS LTDA
A35: 10/2025 | B35: 43633 | C35: Atta | D35: Aramodu | E35: Vesti (Assinatura) | F35: Essencial | H35: 283 | J35: 283 | O35: =SUM(J35:M35)-N35 -> 283 | Q35: 11 | R35: 04 | S35: 97541061000106 | T35: ARAMODU = CONFECCOES ARAMODU EIRELI
A36: 10/2025 | B36: 43643 | C36: Atta | D36: Scera | E36: Vesti (Assinatura) | F36: Essencial | H36: 283 | J36: 283 | O36: =SUM(J36:M36)-N36 -> 283 | Q36: 15 | R36: 04 | S36: 23333642000108 | T36: SCERA = SCERA MODA FEMININA LTDA
A37: 10/2025 | B37: 43649 | C37: Atta | D37: Fama Fashion | E37: Vesti (Assinatura) | F37: Essencial | H37: 283 | J37: 283 | O37: =SUM(J37:M37)-N37 -> 283 | Q37: 20 | R37: 04 | S37: 54451398000101 | T37: FAMA FASHION = FAMA FASHION CREACOES LTDA
A38: 10/2025 | B38: 43649 | C38: VESTI | D38: Paloma Concept | E38: Vesti (Assinatura) | F38: Essencial | H38: 283 | J38: 283 | O38: =SUM(J38:M38)-N38 -> 283 | Q38: 15 | R38: 04 | S38: 16579598000155 | T38: PALOMA CONCEPT = FABIO DE ARAUJO LIMA FERREIRA EIRELI
A39: 10/2025 | B39: 43656 | C39: Atta | D39: Cheers | E39: Vesti (Assinatura) | F39: Profissional | H39: 1179 | J39: 1179 | O39: =SUM(J39:M39)-N39 -> 1179 | Q39: 11 | R39: 04 | S39: 53659785000175 | T39: CHEERS = MODAS VISION LTDA
A40: 10/2025 | B40: 43656 | C40: Atta | D40: Fesperamor | E40: Vesti (Assinatura) | F40: Profissional | H40: 1179 | J40: 1179 | O40: =SUM(J40:M40)-N40 -> 1179 | Q40: 15 | R40: 04 | S40: 22015485000120 | T40: FESPERAMOR = JEH CONFECCOES LTDA
...

Sheet Vesti 1225
A1: Fat.2025 | B1: ANIVERSÁRIO | C1: CANAL | D1: MARCA | E1: Subconta | F1: PLANO | G1: SETUP | H1: MENSALIDADE INICIAL | I1: VALOR REAJUSTE | J1: MENSALIDADE | K1: INTEGRAÇÃO | L1: ASSISTENTE | M1: FILIAL | N1: DESCONTOS | O1: TOTAL COBRADO | P1: OBSERVAÇÕES | Q1: Dia Vencimento | R1: Mês de Reajuste | S1: CPFCNPJ | T1: NOME/RAZÃO SOCIAL
A2: 12/2025 | B2: 42795 | C2: VESTI | D2: TNW Jeans | E2: Vesti (Assinatura) | F2: Profissional | H2: 1156 | J2: 1156 | O2: =SUM(J2:M2)-N2 -> 1156 | Q2: 17 | R2: 04 | S2: 4937453000108 | T2: TNW JEANS = TNW CONFECCOES LTDA
A3: 12/2025 | B3: 42937 | C3: Atta | D3: Peonia | E3: Atta | F3: Essencial | H3: 302 | J3: 302 | O3: =SUM(J3:M3)-N3 -> 302 | Q3: 20 | R3: 4 | S3: 07993188000165
A4: 12/2025 | B4: 43160 | C4: Atta | D4: Maria De Chita | E4: Vesti (Assinatura) | F4: Profissional | H4: 724 | J4: 724 | O4: =SUM(J4:M4)-N4 -> 724 | Q4: 15 | R4: 04 | S4: 07402979000173 | T4: MARIA DE CHITA = MARIA DE CHITA CONFECCOES LTDA
A5: 12/2025 | B5: 43160 | C5: Atta | D5: Shanes | E5: Vesti (Assinatura) | F5: Profissional | H5: 1179 | J5: 1179 | O5: =SUM(J5:M5)-N5 -> 1179 | Q5: 20 | R5: 04 | S5: 46446130000153 | T5: SHANES = CONFECCOES SHANES LTDA
A6: 12/2025 | B6: 43160 | C6: Atta | D6: Talgui | E6: Vesti (Assinatura) | F6: Avançado | H6: 441.33 | J6: 441.33 | O6: =SUM(J6:M6)-N6 -> 441.33 | Q6: 15 | R6: 04 | S6: 05876663000198 | T6: TALGUI = TALGUI CONFECCOES DE ROUPAS LTDA
A7: 12/2025 | B7: 43160 | C7: Atta | D7: Coinage | E7: Vesti (Assinatura) | F7: Profissional | H7: 1179 | J7: 1179 | O7: =SUM(J7:M7)-N7 -> 1179 | Q7: 20 | R7: 04 | S7: 33724927000123 | T7: Coinage = DON IN CONFECCOES LTDA
A8: 12/2025 | B8: 43160 | C8: Atta | D8: Moda Inn | E8: Vesti (Assinatura) | F8: Essencial | H8: 283 | J8: 283 | O8: =SUM(J8:M8)-N8 -> 283 | Q8: 20 | R8: 04 | S8: 49921554000110 | T8: MODA INN = CONFECCOES SIMON LTDA
A9: 12/2025 | B9: 43160 | C9: Atta | D9: Licommo | E9: Vesti (Assinatura) | F9: Avançado | H9: 425 | J9: 425 | O9: =SUM(J9:M9)-N9 -> 425 | Q9: 15 | R9: 04 | S9: 08325746000187 | T9: LICOMMO = CONFECCOES LICOMMO LTDA
A10: 12/2025 | B10: 43160 | C10: Atta | D10: Betsey | E10: Vesti (Assinatura) | F10: Profissional | H10: 1003 | J10: 1003 | O10: =SUM(J10:M10)-N10 -> 1003 | Q10: 15 | R10: 04 | S10: 06161024000109 | T10: BETSEY = BETSEY CONFECCOES LTDA
A11: 12/2025 | B11: 43160 | C11: Atta | D11: Cashier | E11: Vesti (Assinatura) | F11: Profissional | H11: 1015 | J11: 1015 | O11: =SUM(J11:M11)-N11 -> 1015 | Q11: 30 | R11: 04 | S11: 60368669000162 | T11: CASHIER = CASHIER CONFECCOES LTDA
A12: 12/2025 | B12: 43160 | C12: Atta | D12: Cony Green | E12: Vesti (Assinatura) | F12: Avançado | H12: 425 | J12: 425 | O12: =SUM(J12:M12)-N12 -> 425 | Q12: 15 | R12: 04 | S12: 44511277000154 | T12: CONY GREEN = CONFECCOES E MODAS CONY GREEN LTDA
A13: 12/2025 | B13: 43160 | C13: Atta | D13: Pury | E13: Vesti (Assinatura) | F13: Profissional | H13: 1327 | J13: 1327 | M13: 359 | O13: =SUM(J13:M13)-N13 -> 1686 | Q13: 15 | R13: 04 | S13: 12576594000162 | T13: PURY = CONFECCOES PURY LTDA
A14: 12/2025 | B14: 43160 | C14: VESTI | D14: Tricomix | E14: Vesti (Assinatura) | F14: Avançado | H14: 1193 | J14: 1193 | K14: 350 | O14: =SUM(J14:M14)-N14 -> 1543 | Q14: 11 | R14: 04 | S14: 04665515000161 | T14: TRICOMIX = TRICOMIX INDUSTRIA E COMERCIO DE CONFECCOES EIRELI
A15: 12/2025 | B15: 43160 | C15: Atta | D15: Lov It | E15: Vesti (Assinatura) | F15: Avançado | H15: 425 | J15: 425 | O15: =SUM(J15:M15)-N15 -> 425 | Q15: 11 | R15: 04 | S15: 21749422000215 | T15: LOV IT = WELOVIT CONFECCOES LTDA
A16: 12/2025 | B16: 43160 | C16: Atta | D16: Hemix | E16: Vesti (Assinatura) | F16: Essencial | H16: 283 | J16: 283 | L16: =550+120 -> 670 | O16: =SUM(J16:M16)-N16 -> 953 | Q16: 15 | R16: 04 | S16: 07389520000187 | T16: HEMIX = HEMIX CONFECCOES LTDA
A17: 12/2025 | B17: 43160 | C17: Miredata | D17: Mottive | E17: Vesti (Assinatura) | F17: Profissional | H17: 1179 | J17: 1179 | O17: =SUM(J17:M17)-N17 -> 1179 | Q17: 20 | R17: 04 | S17: 24330475000104 | T17: MOTTIVE = PROBELLAS CONFECCOES LTDA EPP
A18: 12/2025 | B18: 43160 | C18: Atta | D18: Miss Alfa | E18: Vesti (Assinatura) | F18: Essencial | H18: 283 | J18: 283 | O18: =SUM(J18:M18)-N18 -> 283 | Q18: 15 | R18: 04 | S18: 28497561000167 | T18: MISS ALFA = MISS ALFA COMERCIO DE ROUPAS LTDA
A19: 12/2025 | B19: 43160 | C19: VESTI | D19: Anemone | E19: Vesti (Assinatura) | F19: Avançado | H19: 1013 | J19: 1013 | O19: =SUM(J19:M19)-N19 -> 1013 | Q19: 11 | R19: 04 | S19: 30962814000178 | T19: ANEMONE = MM21 INDUSTRIA E COMERCIO DE ROUPAS LTDA
A20: 12/2025 | B20: 43160 | C20: Miredata | D20: Pianeta | E20: Vesti (Assinatura) | F20: Profissional | H20: 761 | J20: 761 | O20: =SUM(J20:M20)-N20 -> 761 | Q20: 20 | R20: 04 | S20: 31583000000195 | T20: PIANETA = INTERMIX CONFECCOES DE ROUPAS LTDA
A21: 12/2025 | B21: 43356 | C21: Atta | D21: Morina | E21: Vesti (Assinatura) | F21: Profissional | H21: 1138 | J21: 1138 | O21: =SUM(J21:M21)-N21 -> 1138 | Q21: 15 | R21: 04 | S21: 44029041000186 | T21: Morina = FYK CONFECCOES LTDA
A22: 12/2025 | B22: 43586 | C22: Atta | D22: Artemiss | E22: Vesti (Assinatura) | F22: Avançado | H22: 569 | J22: 569 | M22: 275 | O22: =SUM(J22:M22)-N22 -> 844 | Q22: 11 | R22: 04 | S22: 05320347000135 | T22: ARTEMISS = CONFECCOES ARTE E MISS LTDA
A23: 12/2025 | B23: 43586 | C23: Atta | D23: IT LOOK | E23: Vesti (Assinatura) | F23: Essencial | H23: 283 | J23: 283 | O23: =SUM(J23:M23)-N23 -> 283 | Q23: 15 | R23: 04 | S23: 21659326000103 | T23: IT LOOK = IT LOOK CONFECCAO E COMERCIO DE ROUPAS LTDA
A24: 12/2025 | B24: 43586 | C24: Atta | D24: E YUNIRE | E24: Vesti (Assinatura) | F24: Essencial | H24: 354 | J24: 354 | O24: =SUM(J24:M24)-N24 -> 354 | Q24: 15 | R24: 04 | S24: 45375658000116 | T24: E YUNIRE = YUNIVEST CONFECCOES LTDA
A25: 12/2025 | B25: 43593 | C25: Atta | D25: Incentive | E25: Vesti (Assinatura) | F25: Essencial | H25: 528.33 | J25: 528.33 | O25: =SUM(J25:M25)-N25 -> 528.33 | Q25: 30 | R25: 04 | S25: 29780242000127 | T25: INCENTIVE = CONFECCOES INCENTIVE LTDA
A26: 12/2025 | B26: 43593 | C26: Atta | D26: Mariá/Aurora | E26: Vesti (Assinatura) | F26: Essencial | H26: 283 | J26: 283 | O26: =SUM(J26:M26)-N26 -> 283 | Q26: 20 | R26: 04 | S26: 33076814000169 | T26: Maria/Aurora = OK MI DO
A27: 12/2025 | B27: 43593 | C27: Atta | D27: Mazarin | E27: Vesti (Assinatura) | F27: Essencial | H27: 326.67 | J27: 326.67 | O27: =SUM(J27:M27)-N27 -> 326.67 | Q27: 15 | R27: 04 | S27: 03598605000203 | T27: MAZARIN = CONFECCOES MAZARIN LTDA
A28: 12/2025 | B28: 43600 | C28: Atta | D28: Blue Blossom | E28: Vesti (Assinatura) | F28: Essencial | H28: 283 | J28: 283 | M28: 410 | O28: =SUM(J28:M28)-N28 -> 693 | Q28: 15 | R28: 04 | S28: 30828978000107 | T28: BLUE BLOSSOM = BLUE BLOSSOM CONFECCOES EIRELI
A29: 12/2025 | B29: 43606 | C29: VESTI | D29: Crocker | E29: Vesti (Assinatura) | F29: Profissional | H29: 1179 | J29: 1179 | M29: 410 | O29: =SUM(J29:M29)-N29 -> 1589 | Q29: 15 | R29: 04 | S29: 60652948000153 | T29: CROCKER = US BRASIL INDUSTRIA E COMERCIO DE ROUPAS LTDA
A30: 12/2025 | B30: 43606 | C30: VESTI | D30: Lesto | E30: Vesti (Assinatura) | F30: Essencial | H30: 284.33 | J30: 284.33 | O30: =SUM(J30:M30)-N30 -> 284.33 | Q30: 15 | R30: 04 | S30: 58418377000145 | T30: LESTO = LESTO CONFECCOES LTDA
A31: 12/2025 | B31: 43619 | C31: Atta | D31: Ellen One | E31: Vesti (Cartão) | F31: Essencial | H31: 283 | J31: 283 | O31: =SUM(J31:M31)-N31 -> 283 | Q31: 06 | R31: 4 | S31: 07554437000116 | T31: Ellen One = CONFECCOES ELLEN ONE EIRELI
A32: 12/2025 | B32: 43619 | C32: Atta | D32: Instar | E32: Vesti (Assinatura) | F32: Essencial | H32: 283 | J32: 283 | O32: =SUM(J32:M32)-N32 -> 283 | Q32: 15 | R32: 04 | S32: 32649954000116 | T32: INSTAR = CLASSY MISSY CONFECCAO DE ROUPAS LTDA
A33: 12/2025 | B33: 43633 | C33: Atta | D33: Aramodu | E33: Vesti (Assinatura) | F33: Essencial | H33: 283 | J33: 283 | O33: =SUM(J33:M33)-N33 -> 283 | Q33: 11 | R33: 04 | S33: 97541061000106 | T33: ARAMODU = CONFECCOES ARAMODU EIRELI
A34: 12/2025 | B34: 43643 | C34: Atta | D34: Scera | E34: Vesti (Assinatura) | F34: Essencial | H34: 283 | J34: 283 | O34: =SUM(J34:M34)-N34 -> 283 | Q34: 15 | R34: 04 | S34: 23333642000108 | T34: SCERA = SCERA MODA FEMININA LTDA
A35: 12/2025 | B35: 43649 | C35: Atta | D35: Fama Fashion | E35: Vesti (Assinatura) | F35: Essencial | H35: 283 | J35: 283 | O35: =SUM(J35:M35)-N35 -> 283 | Q35: 20 | R35: 04 | S35: 54451398000101 | T35: FAMA FASHION = FAMA FASHION CREACOES LTDA
A36: 12/2025 | B36: 43649 | C36: VESTI | D36: Paloma Concept | E36: Vesti (Assinatura) | F36: Essencial | H36: 283 | J36: 283 | O36: =SUM(J36:M36)-N36 -> 283 | Q36: 15 | R36: 04 | S36: 16579598000155 | T36: PALOMA CONCEPT = FABIO DE ARAUJO LIMA FERREIRA EIRELI
A37: 12/2025 | B37: 43656 | C37: Atta | D37: Cheers | E37: Vesti (Assinatura) | F37: Profissional | H37: 1179 | J37: 1179 | O37: =SUM(J37:M37)-N37 -> 1179 | Q37: 11 | R37: 04 | S37: 53659785000175 | T37: CHEERS = MODAS VISION LTDA
A38: 12/2025 | B38: 43656 | C38: Atta | D38: Fesperamor | E38: Vesti (Assinatura) | F38: Profissional | H38: 1179 | J38: 1179 | O38: =SUM(J38:M38)-N38 -> 1179 | Q38: 15 | R38: 04 | S38: 22015485000120 | T38: FESPERAMOR = JEH CONFECCOES LTDA
A39: 12/2025 | B39: 43675 | C39: Atta | D39: Quebela | E39: Vesti (Assinatura) | F39: Essencial | H39: 425 | J39: 425 | M39: 369 | O39: =SUM(J39:M39)-N39 -> 794 | Q39: 20 | R39: 04 | S39: 58525007000107 | T39: QUEBELA = CONFECCOES QUEBELA LTDA
A40: 12/2025 | B40: 43684 | C40: Atta | D40: Genesis Jeans | E40: Vesti (Assinatura) | F40: Essencial | H40: 283 | J40: 283 | O40: =SUM(J40:M40)-N40 -> 283 | Q40: 15 | R40: 04 | S40: 21352130000163 | T40: GENESIS JEANS = GENESIS JEANS LTDA
...

Sheet Starter 0126
A1: Fat.2025 | B1: ANIVERSÁRIO | C1: REAJUSTE ANUAL | D1: CANAL/Agência | E1: MARCA | F1: Subconta | G1: PLANO | H1: SETUP | I1: MENSALIDADE INICIAL | J1: VALOR REAJUSTE | K1: MENSALIDADE | L1: INTEGRAÇÃO | M1: ASSISTENTE | N1: FILIAL | O1: DESCONTOS | P1: TOTAL COBRADO | Q1: OBSERVAÇÕES | R1: CPF e CNPJ | S1: Mês de Reajuste
A2: 01/2026 | B2: 45259 | D2: Zoom- Cardume | E2: WA Baby | F2: Vesti (Cartão) | G2: Vesti Light | H2: 0 | I2: 317 | K2: =I2+J2 -> 317 | P2: =SUM(K2:N2)-O2 -> 317 | S2: =MONTH(B2) -> 11
A3: 01/2026 | B3: 45307 | C3: OK | D3: Vesti - Glads | E3: Levitheo | F3: Vesti (Cartão) | G3: Vesti Light | H3: 249 | I3: 267 | K3: =I3+J3 -> 267 | P3: =SUM(K3:N3)-O3 -> 267 | S3: =MONTH(B3) -> 1
A4: 01/2026 | B4: 45315 | C4: OK | D4: Sete | E4: Donna Stella | F4: Vesti (Cartão) | G4: Vesti Light | H4: 249 | I4: 267 | K4: =I4+J4 -> 267 | P4: =SUM(K4:N4)-O4 -> 267 | S4: =MONTH(B4) -> 1
A5: 01/2026 | B5: 45320 | C5: OK | D5: VESTI | E5: Nadri | F5: Vesti (Cartão) | G5: Vesti Light | H5: 249 | I5: 267 | K5: =I5+J5 -> 267 | P5: =SUM(K5:N5)-O5 -> 267 | S5: =MONTH(B5) -> 1
A6: 01/2026 | B6: 45323 | C6: OK | D6: Zoom- Cardume | E6: GO Padel | F6: Vesti (Cartão) | G6: Vesti Light | H6: 249 | I6: 249 | K6: 267 | P6: =SUM(K6:N6)-O6 -> 267 | S6: =MONTH(B6) -> 2
A7: 01/2026 | B7: 45323 | C7: OK | D7: Vesti - Glads | E7: Kroft Oficial | F7: Vesti (Cartão) | G7: Vesti Light | H7: 249 | I7: 249 | K7: 267 | P7: =SUM(K7:N7)-O7 -> 267 | S7: =MONTH(B7) -> 2
A8: 01/2026 | B8: 45337 | C8: OK | D8: Zoom- Cardume | E8: Divas Vero | F8: Vesti (Cartão) | G8: Vesti Light | H8: 249 | I8: 249 | K8: 267 | P8: =SUM(K8:N8)-O8 -> 267 | S8: =MONTH(B8) -> 2
A9: 01/2026 | B9: 45342 | C9: OK | D9: Vesti - ProRoi | E9: Repete Conf | F9: Vesti (Cartão) | G9: Vesti Light | H9: 249 | I9: 249 | K9: 267 | P9: =SUM(K9:N9)-O9 -> 267 | S9: =MONTH(B9) -> 2
A10: 01/2026 | B10: 45352 | D10: Sete | E10: Monnika Marikinha Brand | F10: Vesti (Cartão) | G10: Vesti Light | H10: 249 | I10: 249 | K10: 267 | P10: =SUM(K10:N10)-O10 -> 267 | S10: =MONTH(B10) -> 3
A11: 01/2026 | B11: 45352 | D11: Vesti - ProRoi | E11: RED ROCK (R) | F11: ProRoi | G11: Vesti Light | H11: 249 | I11: 249 | K11: 267 | P11: =SUM(K11:N11)-O11 -> 267 | S11: =MONTH(B11) -> 3
A12: 01/2026 | B12: 45363 | D12: Sete | E12: Fabio's Moda Intima | F12: Vesti (Cartão) | G12: Vesti Light | H12: 249 | I12: 249 | K12: 267 | P12: =SUM(K12:N12)-O12 -> 267 | S12: =MONTH(B12) -> 3
A13: 01/2026 | B13: 45379 | D13: Zoom- Cardume | E13: RL Modas | F13: Vesti (Cartão) | G13: Vesti Light | H13: 249 | I13: 249 | K13: 267 | P13: =SUM(K13:N13)-O13 -> 267 | S13: =MONTH(B13) -> 3
A14: 01/2026 | B14: 45393 | D14: Vesti - Tizzefy | E14: Aline Confecções | F14: Vesti (Cartão) | G14: Vesti Light | H14: 249 | I14: 267 | K14: 267 | P14: =SUM(K14:N14)-O14 -> 267 | S14: =MONTH(B14) -> 4
A15: 01/2026 | B15: 45411 | D15: Vesti - Tizzefy | E15: Igmar | F15: Vesti (Cartão) | G15: Vesti Light | H15: 249 | I15: 267 | K15: 267 | P15: =SUM(K15:N15)-O15 -> 267 | S15: =MONTH(B15) -> 4
A16: 01/2026 | B16: 45418 | D16: Vesti - Tizzefy | E16: Worldstar Lingerie | F16: Vesti (Cartão) | G16: Vesti Light | H16: 249 | I16: 267 | K16: 267 | P16: =SUM(K16:N16)-O16 -> 267 | S16: =MONTH(B16) -> 5
A17: 01/2026 | B17: 45425 | D17: Vesti - ProRoi | E17: Bella Fe | F17: Vesti (Cartão) | G17: Vesti Light | H17: 249 | I17: 267 | K17: 267 | P17: =SUM(K17:N17)-O17 -> 267 | S17: =MONTH(B17) -> 5
A18: 01/2026 | B18: 45434 | C18: ok | D18: Vesti - ProRoi | E18: RIBELIM | F18: Vesti - ProRoi | G18: Vesti Light | H18: 249 | I18: 285 | K18: 285 | P18: =SUM(K18:N18)-O18 -> 285 | S18: =MONTH(B18) -> 5
A19: 01/2026 | B19: 45446 | C19: ok | D19: VESTI | E19: Lupus Wear | F19: Vesti Light | G19: Vesti Light | H19: 249 | I19: 267 | K19: 267 | P19: =SUM(K19:N19)-O19 -> 267 | S19: =MONTH(B19) -> 6
A20: 01/2026 | B20: 45448 | C20: ok | D20: Zoom- Cardume | E20: Felps Confecções | F20: Vesti Light | G20: Vesti Light | H20: 0 | I20: 267 | K20: 267 | P20: =SUM(K20:N20)-O20 -> 267 | S20: =MONTH(B20) -> 6
A21: 01/2026 | B21: 45457 | C21: ok | D21: Vesti - Tizzefy | E21: MINOLLI | F21: Vesti - Tizzefy | G21: Vesti Light | H21: 249 | I21: 267 | K21: 267 | P21: =SUM(K21:N21)-O21 -> 267 | S21: =MONTH(B21) -> 6
A22: 01/2026 | B22: 45462 | C22: ok | D22: VESTI | E22: Urban Race | F22: Vesti Light | G22: Vesti Light | H22: 299 | I22: 317 | K22: 317 | P22: =SUM(K22:N22)-O22 -> 317 | S22: =MONTH(B22) -> 6
A23: 01/2026 | B23: 45462 | C23: ok | D23: VESTI | E23: Planet Charm | F23: Vesti Light | G23: Vesti Light | H23: 299 | I23: 317 | K23: 317 | P23: =SUM(K23:N23)-O23 -> 317 | S23: =MONTH(B23) -> 6
A24: 01/2026 | B24: 45489 | D24: Vê Vantagens | E24: PEROLA ORIENTAL LK&D | F24: Vê Vantagens | G24: Vesti Light | H24: 249 | I24: 267 | K24: 267 | P24: =SUM(K24:N24)-O24 -> 267 | S24: =MONTH(B24) -> 7
A25: 01/2026 | B25: 45498 | D25: VESTI | E25: IZZA PVH | F25: Vesti Multimarcas | G25: Vesti Multimarca | H25: 99 | I25: 99 | K25: 99 | P25: =SUM(K25:N25)-O25 -> 99 | R25: 31506519000170 | S25: =MONTH(B25) -> 7
A26: 01/2026 | B26: 45500 | D26: Vesti - ProRoi | E26: BegKids | F26: Vesti - ProRoi | G26: Vesti Light | H26: 299 | I26: 317 | K26: 317 | P26: =SUM(K26:N26)-O26 -> 317 | S26: =MONTH(B26) -> 7
A27: 01/2026 | B27: 45501 | D27: VESTI | E27: Agridoce | F27: Vesti Light | G27: Vesti Light | H27: 699 | I27: 299 | K27: 299 | P27: =SUM(K27:N27)-O27 -> 299 | S27: =MONTH(B27) -> 7
A28: 01/2026 | B28: 45505 | C28: OK | D28: VESTI | E28: Arary | F28: Vesti Light | G28: Vesti Light | H28: 299 | I28: 317 | K28: 317 | P28: =SUM(K28:N28)-O28 -> 317 | S28: =MONTH(B28) -> 8
A29: 01/2026 | B29: 45506 | C29: OK | D29: Vê Vantagens | E29: Aurami | F29: Vê Vantagens | G29: Vesti Light | H29: 299 | I29: 317 | K29: 317 | P29: =SUM(K29:N29)-O29 -> 317 | S29: =MONTH(B29) -> 8
A30: 01/2026 | B30: 45509 | C30: OK | D30: VESTI | E30: Valentina Fashion | F30: Vesti Multimarcas | G30: Vesti Multimarca | H30: 99 | I30: 117 | K30: 117 | O30: 18 | P30: =SUM(K30:N30)-O30 -> 99 | R30: 39554207000143 | S30: =MONTH(B30) -> 8
A31: 01/2026 | B31: 45506 | C31: OK | D31: VESTI | E31: TNT Moda Fitness | F31: Vesti Light | G31: Vesti Light | H31: 299 | I31: 317 | K31: 317 | P31: =SUM(K31:N31)-O31 -> 317 | S31: =MONTH(B31) -> 8
A32: 01/2026 | B32: 45519 | C32: OK | D32: Vê Vantagens | E32: PEROLA ORIENTAL = M&K | F32: Vê Vantagens | G32: Vesti Light | H32: 299 | I32: 267 | K32: 267 | P32: =SUM(K32:N32)-O32 -> 267 | S32: =MONTH(B32) -> 8
A33: 01/2026 | B33: 45532 | C33: OK | D33: VESTI | E33: Lado Doce | F33: Vesti Light | G33: Vesti Light | H33: 800 | I33: 317 | K33: 317 | P33: =SUM(K33:N33)-O33 -> 317 | S33: =MONTH(B33) -> 8
A34: 01/2026 | B34: 45533 | C34: OK | D34: VESTI | E34: Espaço Berta | F34: Vesti Multimarcas | G34: Vesti Multimarca | H34: 99 | I34: 99 | K34: 99 | P34: =SUM(K34:N34)-O34 -> 99 | R34: 25225294120 | S34: =MONTH(B34) -> 8
A35: 01/2026 | B35: 45533 | C35: OK | D35: VESTI | E35: A Rouparia | F35: Vesti Multimarcas | G35: Vesti Multimarca | H35: 99 | I35: 117 | K35: 117 | P35: =SUM(K35:N35)-O35 -> 117 | R35: 32979501000158 | S35: =MONTH(B35) -> 8
A36: 01/2026 | B36: 45539 | C36: ok | D36: VESTI | E36: Drika Confeccoes | F36: Vesti Light | G36: Vesti Light | H36: 800 | I36: 317 | K36: 317 | P36: =SUM(K36:N36)-O36 -> 317 | S36: =MONTH(B36) -> 9
A37: 01/2026 | B37: 45539 | C37: ok | D37: Vesti - Tizzefy | E37: VLY JEANS | F37: Vesti - Tizzefy | G37: Vesti Light | H37: 800 | I37: 267 | K37: 267 | P37: =SUM(K37:N37)-O37 -> 267 | S37: =MONTH(B37) -> 9
A38: 01/2026 | B38: 45539 | C38: ok | D38: VESTI | E38: Veste Vegana | F38: Vesti Light | G38: Vesti Light | H38: 249 | I38: 267 | K38: 267 | P38: =SUM(K38:N38)-O38 -> 267 | S38: =MONTH(B38) -> 9
A39: 01/2026 | B39: 45541 | C39: ok | D39: VESTI | E39: Dominio​ Conceito | F39: Vesti Light | G39: Vesti Light | H39: =800+299 -> 1099 | I39: 317 | K39: 317 | P39: =SUM(K39:N39)-O39 -> 317 | S39: =MONTH(B39) -> 9
A40: 01/2026 | B40: 45547 | C40: ok | D40: VESTI | E40: Alice Amaral Brand Store | F40: Vesti Multimarcas | G40: Vesti Multimarca | H40: 99 | I40: 99 | K40: 99 | P40: =SUM(K40:N40)-O40 -> 99 | R40: 30707302000165 | S40: =MONTH(B40) -> 9
...

Sheet Vesti 012026
A1: Fat.2025 | B1: ANIVERSÁRIO | C1: REAJUSTE ANUAL | D1: CANAL | E1: MARCA | F1: Subconta | G1: PLANO | H1: SETUP | I1: MENSALIDADE INICIAL | J1: VALOR REAJUSTE | K1: MENSALIDADE | L1: INTEGRAÇÃO | M1: ASSISTENTE | N1: FILIAL | O1: DESCONTOS | P1: TOTAL COBRADO | Q1: OBSERVAÇÕES | R1: Dia Vencimento | S1: Mês de Reajuste | T1: CPFCNPJ | U1: NOME/RAZÃO SOCIAL
A2: 01/2026 | B2: 42795 | D2: VESTI | E2: TNW Jeans | F2: Vesti (Assinatura) | G2: Profissional | I2: 1156 | K2: 1156 | P2: =SUM(K2:N2)-O2 -> 1156 | R2: 17 | S2: 04 | T2: 4937453000108 | U2: TNW JEANS = TNW CONFECCOES LTDA
A3: 01/2026 | B3: 42937 | C3: ok | D3: Atta | E3: Peonia | F3: Atta | G3: Essencial | I3: 302 | K3: 302 | P3: =SUM(K3:N3)-O3 -> 302 | R3: 20 | S3: 4 | T3: 07993188000165
A4: 01/2026 | B4: 43160 | D4: Atta | E4: Maria De Chita | F4: Vesti (Assinatura) | G4: Profissional | I4: 724 | K4: 724 | P4: =SUM(K4:N4)-O4 -> 724 | R4: 15 | S4: 04 | T4: 07402979000173 | U4: MARIA DE CHITA = MARIA DE CHITA CONFECCOES LTDA
A5: 01/2026 | B5: 43160 | D5: Atta | E5: Shanes | F5: Vesti (Assinatura) | G5: Profissional | I5: 1179 | K5: 1179 | P5: =SUM(K5:N5)-O5 -> 1179 | R5: 20 | S5: 04 | T5: 46446130000153 | U5: SHANES = CONFECCOES SHANES LTDA
A6: 01/2026 | B6: 43160 | D6: Atta | E6: Talgui | F6: Vesti (Assinatura) | G6: Avançado | I6: 441.33 | K6: 441.33 | P6: =SUM(K6:N6)-O6 -> 441.33 | R6: 15 | S6: 04 | T6: 05876663000198 | U6: TALGUI = TALGUI CONFECCOES DE ROUPAS LTDA
A7: 01/2026 | B7: 43160 | D7: Atta | E7: Coinage | F7: Vesti (Assinatura) | G7: Profissional | I7: 1179 | K7: 1179 | P7: =SUM(K7:N7)-O7 -> 1179 | R7: 20 | S7: 04 | T7: 33724927000123 | U7: Coinage = DON IN CONFECCOES LTDA
A8: 01/2026 | B8: 43160 | D8: Atta | E8: Moda Inn | F8: Vesti (Assinatura) | G8: Essencial | I8: 283 | K8: 283 | P8: =SUM(K8:N8)-O8 -> 283 | R8: 20 | S8: 04 | T8: 49921554000110 | U8: MODA INN = CONFECCOES SIMON LTDA
A9: 01/2026 | B9: 43160 | D9: Atta | E9: Betsey | F9: Vesti (Assinatura) | G9: Profissional | I9: 1003 | K9: 1003 | P9: =SUM(K9:N9)-O9 -> 1003 | R9: 15 | S9: 04 | T9: 06161024000109 | U9: BETSEY = BETSEY CONFECCOES LTDA
A10: 01/2026 | B10: 43160 | D10: Atta | E10: Cashier | F10: Vesti (Assinatura) | G10: Profissional | I10: 1015 | K10: 1015 | P10: =SUM(K10:N10)-O10 -> 1015 | R10: 30 | S10: 04 | T10: 60368669000162 | U10: CASHIER = CASHIER CONFECCOES LTDA
A11: 01/2026 | B11: 43160 | D11: Atta | E11: Cony Green | F11: Vesti (Assinatura) | G11: Avançado | I11: 425 | K11: 425 | P11: =SUM(K11:N11)-O11 -> 425 | R11: 15 | S11: 04 | T11: 44511277000154 | U11: CONY GREEN = CONFECCOES E MODAS CONY GREEN LTDA
A12: 01/2026 | B12: 43160 | D12: Atta | E12: Pury | F12: Vesti (Assinatura) | G12: Profissional | I12: 1327 | K12: 1327 | N12: 359 | P12: =SUM(K12:N12)-O12 -> 1686 | R12: 15 | S12: 04 | T12: 12576594000162 | U12: PURY = CONFECCOES PURY LTDA
A13: 01/2026 | B13: 43160 | D13: VESTI | E13: Tricomix | F13: Vesti (Assinatura) | G13: Avançado | I13: 1193 | K13: 1193 | L13: 350 | P13: =SUM(K13:N13)-O13 -> 1543 | R13: 11 | S13: 04 | T13: 04665515000161 | U13: TRICOMIX = TRICOMIX INDUSTRIA E COMERCIO DE CONFECCOES EIRELI
A14: 01/2026 | B14: 43160 | D14: Atta | E14: Lov It | F14: Vesti (Assinatura) | G14: Avançado | I14: 425 | K14: 425 | P14: =SUM(K14:N14)-O14 -> 425 | R14: 11 | S14: 04 | T14: 21749422000215 | U14: LOV IT = WELOVIT CONFECCOES LTDA
A15: 01/2026 | B15: 43160 | D15: Atta | E15: Hemix | F15: Vesti (Assinatura) | G15: Essencial | I15: 283 | K15: 283 | M15: =550+120 -> 670 | P15: =SUM(K15:N15)-O15 -> 953 | R15: 15 | S15: 04 | T15: 07389520000187 | U15: HEMIX = HEMIX CONFECCOES LTDA
A16: 01/2026 | B16: 43160 | D16: Miredata | E16: Mottive | F16: Vesti (Assinatura) | G16: Profissional | I16: 1179 | K16: 1179 | P16: =SUM(K16:N16)-O16 -> 1179 | R16: 20 | S16: 04 | T16: 24330475000104 | U16: MOTTIVE = PROBELLAS CONFECCOES LTDA EPP
A17: 01/2026 | B17: 43160 | D17: Atta | E17: Miss Alfa | F17: Vesti (Assinatura) | G17: Essencial | I17: 283 | K17: 283 | P17: =SUM(K17:N17)-O17 -> 283 | R17: 15 | S17: 04 | T17: 28497561000167 | U17: MISS ALFA = MISS ALFA COMERCIO DE ROUPAS LTDA
A18: 01/2026 | B18: 43160 | D18: VESTI | E18: Anemone | F18: Vesti (Assinatura) | G18: Avançado | I18: 1013 | K18: 1013 | P18: =SUM(K18:N18)-O18 -> 1013 | R18: 11 | S18: 04 | T18: 30962814000178 | U18: ANEMONE = MM21 INDUSTRIA E COMERCIO DE ROUPAS LTDA
A19: 01/2026 | B19: 43160 | D19: Miredata | E19: Pianeta | F19: Vesti (Assinatura) | G19: Profissional | I19: 761 | K19: 761 | P19: =SUM(K19:N19)-O19 -> 761 | R19: 20 | S19: 04 | T19: 31583000000195 | U19: PIANETA = INTERMIX CONFECCOES DE ROUPAS LTDA
A20: 01/2026 | B20: 43356 | D20: Atta | E20: Morina | F20: Vesti (Assinatura) | G20: Profissional | I20: 1138 | K20: 1138 | P20: =SUM(K20:N20)-O20 -> 1138 | R20: 15 | S20: 04 | T20: 44029041000186 | U20: Morina = FYK CONFECCOES LTDA
A21: 01/2026 | B21: 43586 | D21: Atta | E21: Artemiss | F21: Vesti (Assinatura) | G21: Avançado | I21: 569 | K21: 569 | N21: 275 | P21: =SUM(K21:N21)-O21 -> 844 | R21: 11 | S21: 04 | T21: 05320347000135 | U21: ARTEMISS = CONFECCOES ARTE E MISS LTDA
A22: 01/2026 | B22: 43586 | D22: Atta | E22: IT LOOK | F22: Vesti (Assinatura) | G22: Essencial | I22: 283 | K22: 283 | P22: =SUM(K22:N22)-O22 -> 283 | R22: 15 | S22: 04 | T22: 21659326000103 | U22: IT LOOK = IT LOOK CONFECCAO E COMERCIO DE ROUPAS LTDA
A23: 01/2026 | B23: 43586 | D23: Atta | E23: E YUNIRE | F23: Vesti (Assinatura) | G23: Essencial | I23: 354 | K23: 354 | P23: =SUM(K23:N23)-O23 -> 354 | R23: 15 | S23: 04 | T23: 45375658000116 | U23: E YUNIRE = YUNIVEST CONFECCOES LTDA
A24: 01/2026 | B24: 43593 | D24: Atta | E24: Incentive | F24: Vesti (Assinatura) | G24: Essencial | I24: 528.33 | K24: 528.33 | P24: =SUM(K24:N24)-O24 -> 528.33 | R24: 30 | S24: 04 | T24: 29780242000127 | U24: INCENTIVE = CONFECCOES INCENTIVE LTDA
A25: 01/2026 | B25: 43593 | D25: Atta | E25: Mazarin | F25: Vesti (Assinatura) | G25: Essencial | I25: 326.67 | K25: 326.67 | P25: =SUM(K25:N25)-O25 -> 326.67 | R25: 15 | S25: 04 | T25: 03598605000203 | U25: MAZARIN = CONFECCOES MAZARIN LTDA
A26: 01/2026 | B26: 43600 | D26: Atta | E26: Blue Blossom | F26: Vesti (Assinatura) | G26: Essencial | I26: 283 | K26: 283 | N26: 410 | P26: =SUM(K26:N26)-O26 -> 693 | R26: 15 | S26: 04 | T26: 30828978000107 | U26: BLUE BLOSSOM = BLUE BLOSSOM CONFECCOES EIRELI
A27: 01/2026 | B27: 43606 | D27: VESTI | E27: Crocker | F27: Vesti (Assinatura) | G27: Profissional | I27: 1179 | K27: 1179 | N27: 410 | P27: =SUM(K27:N27)-O27 -> 1589 | R27: 15 | S27: 04 | T27: 60652948000153 | U27: CROCKER = US BRASIL INDUSTRIA E COMERCIO DE ROUPAS LTDA
A28: 01/2026 | B28: 43606 | D28: VESTI | E28: Lesto | F28: Vesti (Assinatura) | G28: Essencial | I28: 284.33 | K28: 284.33 | P28: =SUM(K28:N28)-O28 -> 284.33 | R28: 15 | S28: 04 | T28: 58418377000145 | U28: LESTO = LESTO CONFECCOES LTDA
A29: 01/2026 | B29: 43619 | D29: Atta | E29: Ellen One | F29: Vesti (Cartão) | G29: Essencial | I29: 283 | K29: 283 | P29: =SUM(K29:N29)-O29 -> 283 | R29: 06 | S29: 4 | T29: 07554437000116 | U29: Ellen One = CONFECCOES ELLEN ONE EIRELI
A30: 01/2026 | B30: 43619 | D30: Atta | E30: Instar | F30: Vesti (Assinatura) | G30: Essencial | I30: 283 | K30: 283 | P30: =SUM(K30:N30)-O30 -> 283 | R30: 15 | S30: 04 | T30: 32649954000116 | U30: INSTAR = CLASSY MISSY CONFECCAO DE ROUPAS LTDA
A31: 01/2026 | B31: 43633 | D31: Atta | E31: Aramodu | F31: Vesti (Assinatura) | G31: Essencial | I31: 283 | K31: 283 | P31: =SUM(K31:N31)-O31 -> 283 | R31: 11 | S31: 04 | T31: 97541061000106 | U31: ARAMODU = CONFECCOES ARAMODU EIRELI
A32: 01/2026 | B32: 43643 | D32: Atta | E32: Scera | F32: Vesti (Assinatura) | G32: Essencial | I32: 283 | K32: 283 | O32: 283 | P32: =SUM(K32:N32)-O32 -> 0 | Q32: Desconto concedido devido a marca ter cancelado a filial em setembro e ter sido cobrado por dois meses. cobrar em 02/2025 | R32: 15 | S32: 04 | T32: 23333642000108 | U32: SCERA = SCERA MODA FEMININA LTDA
A33: 01/2026 | B33: 43649 | C33: ok | D33: Atta | E33: Fama Fashion | F33: Vesti (Assinatura) | G33: Essencial | I33: 283 | K33: 283 | P33: =SUM(K33:N33)-O33 -> 283 | R33: 20 | S33: 04 | T33: 54451398000101 | U33: FAMA FASHION = FAMA FASHION CREACOES LTDA
A34: 01/2026 | B34: 43649 | C34: ok | D34: VESTI | E34: Paloma Concept | F34: Vesti (Assinatura) | G34: Essencial | I34: 283 | K34: 283 | P34: =SUM(K34:N34)-O34 -> 283 | R34: 15 | S34: 04 | T34: 16579598000155 | U34: PALOMA CONCEPT = FABIO DE ARAUJO LIMA FERREIRA EIRELI
A35: 01/2026 | B35: 43656 | C35: ok | D35: Atta | E35: Cheers | F35: Vesti (Assinatura) | G35: Profissional | I35: 1179 | K35: 1179 | P35: =SUM(K35:N35)-O35 -> 1179 | R35: 11 | S35: 04 | T35: 53659785000175 | U35: CHEERS = MODAS VISION LTDA
A36: 01/2026 | B36: 43656 | C36: ok | D36: Atta | E36: Fesperamor | F36: Vesti (Assinatura) | G36: Profissional | I36: 1179 | K36: 1179 | P36: =SUM(K36:N36)-O36 -> 1179 | R36: 15 | S36: 04 | T36: 22015485000120 | U36: FESPERAMOR = JEH CONFECCOES LTDA
A37: 01/2026 | B37: 43675 | C37: ok | D37: Atta | E37: Quebela | F37: Vesti (Assinatura) | G37: Essencial | I37: 425 | K37: 425 | N37: 369 | P37: =SUM(K37:N37)-O37 -> 794 | R37: 20 | S37: 04 | T37: 58525007000107 | U37: QUEBELA = CONFECCOES QUEBELA LTDA
A38: 01/2026 | B38: 43684 | D38: Atta | E38: Genesis Jeans | F38: Vesti (Assinatura) | G38: Essencial | I38: 283 | K38: 283 | P38: =SUM(K38:N38)-O38 -> 283 | R38: 15 | S38: 04 | T38: 21352130000163 | U38: GENESIS JEANS = GENESIS JEANS LTDA
A39: 01/2026 | B39: 43713 | D39: Vesti | E39: AMISKA - MISS MILLIE | F39: Vesti (Assinatura) | G39: Essencial | I39: 303 | K39: 303 | P39: =SUM(K39:N39)-O39 -> 303 | R39: 15 | S39: 04 | T39: 24721940000138 | U39: AMISKA MISS MILLIE = CONFECCOES MISS MILLIE INDUSTRIA E COMERCIO DE ROUPAS LTDA EPP
A40: 01/2026 | B40: 43718 | D40: VESTI | E40: Join Curves | F40: Vesti (Assinatura) | G40: Avançado | I40: 486 | K40: 486 | M40: 1000 | N40: 600 | P40: =SUM(K40:N40)-O40 -> 2086 | R40: 28 | S40: 04 | T40: 07867580000168 | U40: Join Curves = JULIA A H INDUSTRIA E COMERCIO DE ROUPAS LTDA
...

Sheet Starter 032026
A1: Fat.2026 | B1: ANIVERSÁRIO | C1: CANAL/Agência | D1: MARCA | E1: Subconta | F1: PLANO | G1: SETUP | H1: MENSALIDADE INICIAL | I1: VALOR REAJUSTE | J1: MENSALIDADE | K1: INTEGRAÇÃO | L1: ASSISTENTE | M1: FILIAL | N1: DESCONTOS | O1: TOTAL COBRADO | P1: OBSERVAÇÕES | Q1: CPF e CNPJ | R1: Mês de Reajuste
A2: 03/2026 | B2: 45259 | C2: Zoom- Cardume | D2: WA Baby | E2: Vesti (Cartão) | F2: Vesti Light | G2: 0 | H2: 317 | J2: =H2+I2 -> 317 | O2: =SUM(J2:M2)-N2 -> 317 | R2: =MONTH(B2) -> 11
A3: 03/2026 | B3: 45307 | C3: Vesti - Glads | D3: Levitheo | E3: Vesti (Cartão) | F3: Vesti Light | G3: 249 | H3: 267 | J3: 285 | O3: =SUM(J3:M3)-N3 -> 285 | R3: 01
A4: 03/2026 | B4: 45315 | C4: Sete | D4: Donna Stella | E4: Vesti (Cartão) | F4: Vesti Light | G4: 249 | H4: 267 | J4: 285 | O4: =SUM(J4:M4)-N4 -> 285 | R4: 01
A5: 03/2026 | B5: 45320 | C5: VESTI | D5: Nadri | E5: Vesti (Cartão) | F5: Vesti Light | G5: 249 | H5: 267 | J5: 285 | O5: =SUM(J5:M5)-N5 -> 285 | R5: 01
A6: 03/2026 | B6: 45323 | C6: Zoom- Cardume | D6: GO Padel | E6: Vesti (Cartão) | F6: Vesti Light | G6: 249 | H6: 285 | J6: 285 | O6: =SUM(J6:M6)-N6 -> 285 | R6: 02
A7: 03/2026 | B7: 45323 | C7: Vesti - Glads | D7: Kroft Oficial | E7: Vesti (Cartão) | F7: Vesti Light | G7: 249 | H7: 285 | J7: 285 | O7: =SUM(J7:M7)-N7 -> 285 | R7: 02
A8: 03/2026 | B8: 45337 | C8: Zoom- Cardume | D8: Divas Vero | E8: Vesti (Cartão) | F8: Vesti Light | G8: 249 | H8: 285 | J8: 285 | O8: =SUM(J8:M8)-N8 -> 285 | R8: 02
A9: 03/2026 | B9: 45342 | C9: Vesti - ProRoi | D9: Repete Conf | E9: Vesti (Cartão) | F9: Vesti Light | G9: 249 | H9: 285 | J9: 285 | O9: =SUM(J9:M9)-N9 -> 285 | R9: 02
A10: 03/2026 | B10: 45352 | C10: Sete | D10: Monnika Marikinha Brand | E10: Vesti (Cartão) | F10: Vesti Light | G10: 249 | H10: 249 | J10: 267 | O10: =SUM(J10:M10)-N10 -> 267 | R10: =MONTH(B10) -> 3
A11: 03/2026 | B11: 45352 | C11: Vesti - ProRoi | D11: RED ROCK (R) | E11: ProRoi | F11: Vesti Light | G11: 249 | H11: 249 | J11: 267 | O11: =SUM(J11:M11)-N11 -> 267 | P11: Redline | Q11: 18.623.259.0001-54 | R11: =MONTH(B11) -> 3
A12: 03/2026 | B12: 45379 | C12: Zoom- Cardume | D12: RL Modas | E12: Vesti (Cartão) | F12: Vesti Light | G12: 249 | H12: 249 | J12: 267 | O12: =SUM(J12:M12)-N12 -> 267 | R12: =MONTH(B12) -> 3
A13: 03/2026 | B13: 45393 | C13: Vesti - Tizzefy | D13: Aline Confecções | E13: Vesti (Cartão) | F13: Vesti Light | G13: 249 | H13: 267 | J13: 267 | O13: =SUM(J13:M13)-N13 -> 267 | R13: =MONTH(B13) -> 4
A14: 03/2026 | B14: 45411 | C14: Vesti - Tizzefy | D14: Igmar | E14: Vesti (Cartão) | F14: Vesti Light | G14: 249 | H14: 267 | J14: 267 | O14: =SUM(J14:M14)-N14 -> 267 | R14: =MONTH(B14) -> 4
A15: 03/2026 | B15: 45425 | C15: Vesti - ProRoi | D15: Bella Fe | E15: Vesti (Cartão) | F15: Vesti Light | G15: 249 | H15: 267 | J15: 267 | O15: =SUM(J15:M15)-N15 -> 267 | R15: =MONTH(B15) -> 5
A16: 03/2026 | B16: 45446 | C16: VESTI | D16: Lupus Wear | E16: Vesti Light | F16: Vesti Light | G16: 249 | H16: 267 | J16: 267 | O16: =SUM(J16:M16)-N16 -> 267 | R16: =MONTH(B16) -> 6
A17: 03/2026 | B17: 45448 | C17: Zoom- Cardume | D17: Felps Confecções | E17: Vesti Light | F17: Vesti Light | G17: 0 | H17: 267 | J17: 267 | O17: =SUM(J17:M17)-N17 -> 267 | R17: =MONTH(B17) -> 6
A18: 03/2026 | B18: 45457 | C18: Vesti - Tizzefy | D18: MINOLLI | E18: Vesti - Tizzefy | F18: Vesti Light | G18: 249 | H18: 267 | J18: 267 | O18: =SUM(J18:M18)-N18 -> 267 | R18: =MONTH(B18) -> 6
A19: 03/2026 | B19: 45462 | C19: VESTI | D19: Urban Race | E19: Vesti Light | F19: Vesti Light | G19: 299 | H19: 317 | J19: 317 | O19: =SUM(J19:M19)-N19 -> 317 | R19: =MONTH(B19) -> 6
A20: 03/2026 | B20: 45462 | C20: VESTI | D20: Planet Charm | E20: Vesti Light | F20: Vesti Light | G20: 299 | H20: 317 | J20: 317 | O20: =SUM(J20:M20)-N20 -> 317 | R20: =MONTH(B20) -> 6
A21: 03/2026 | B21: 45489 | C21: Vê Vantagens | D21: PEROLA ORIENTAL LK&D | E21: Vê Vantagens | F21: Vesti Light | G21: 249 | H21: 267 | J21: 267 | O21: =SUM(J21:M21)-N21 -> 267 | R21: =MONTH(B21) -> 7
A22: 03/2026 | B22: 45498 | C22: VESTI | D22: IZZA PVH | E22: Vesti Multimarcas | F22: Vesti Multimarca | G22: 99 | H22: 99 | J22: 99 | O22: =SUM(J22:M22)-N22 -> 99 | Q22: 31506519000170 | R22: =MONTH(B22) -> 7
A23: 03/2026 | B23: 45500 | C23: Vesti - ProRoi | D23: BegKids | E23: Vesti - ProRoi | F23: Vesti Light | G23: 299 | H23: 317 | J23: 317 | O23: =SUM(J23:M23)-N23 -> 317 | R23: =MONTH(B23) -> 7
A24: 03/2026 | B24: 45501 | C24: VESTI | D24: Agridoce | E24: Vesti Light | F24: Vesti Light | G24: 699 | H24: 299 | J24: 299 | O24: =SUM(J24:M24)-N24 -> 299 | R24: =MONTH(B24) -> 7
A25: 03/2026 | B25: 45505 | C25: VESTI | D25: Arary | E25: Vesti Light | F25: Vesti Light | G25: 299 | H25: 317 | J25: 317 | O25: =SUM(J25:M25)-N25 -> 317 | R25: =MONTH(B25) -> 8
A26: 03/2026 | B26: 45506 | C26: Vê Vantagens | D26: Aurami | E26: Vê Vantagens | F26: Vesti Light | G26: 299 | H26: 317 | J26: 317 | O26: =SUM(J26:M26)-N26 -> 317 | R26: =MONTH(B26) -> 8
A27: 03/2026 | B27: 45509 | C27: VESTI | D27: Valentina Fashion | E27: Vesti Multimarcas | F27: Vesti Multimarca | G27: 99 | H27: 117 | J27: 117 | N27: 18 | O27: =SUM(J27:M27)-N27 -> 99 | Q27: 39554207000143 | R27: =MONTH(B27) -> 8
A28: 03/2026 | B28: 45506 | C28: VESTI | D28: TNT Moda Fitness | E28: Vesti Light | F28: Vesti Light | G28: 299 | H28: 317 | J28: 317 | O28: =SUM(J28:M28)-N28 -> 317 | R28: =MONTH(B28) -> 8
A29: 03/2026 | B29: 45519 | C29: Vê Vantagens | D29: PEROLA ORIENTAL = M&K | E29: Vê Vantagens | F29: Vesti Light | G29: 299 | H29: 267 | J29: 267 | O29: =SUM(J29:M29)-N29 -> 267 | R29: =MONTH(B29) -> 8
A30: 03/2026 | B30: 45532 | C30: VESTI | D30: Lado Doce | E30: Vesti Light | F30: Vesti Light | G30: 800 | H30: 317 | J30: 317 | O30: =SUM(J30:M30)-N30 -> 317 | R30: =MONTH(B30) -> 8
A31: 03/2026 | B31: 45533 | C31: VESTI | D31: Espaço Berta | E31: Vesti Multimarcas | F31: Vesti Multimarca | G31: 99 | H31: 99 | J31: 99 | O31: =SUM(J31:M31)-N31 -> 99 | Q31: 25225294120 | R31: =MONTH(B31) -> 8
A32: 03/2026 | B32: 45533 | C32: VESTI | D32: A Rouparia | E32: Vesti Multimarcas | F32: Vesti Multimarca | G32: 99 | H32: 117 | J32: 117 | O32: =SUM(J32:M32)-N32 -> 117 | Q32: 32979501000158 | R32: =MONTH(B32) -> 8
A33: 03/2026 | B33: 45539 | C33: VESTI | D33: Drika Confeccoes | E33: Vesti Light | F33: Vesti Light | G33: 800 | H33: 317 | J33: 317 | O33: =SUM(J33:M33)-N33 -> 317 | R33: =MONTH(B33) -> 9
A34: 03/2026 | B34: 45539 | C34: Vesti - Tizzefy | D34: VLY JEANS | E34: Vesti - Tizzefy | F34: Vesti Light | G34: 800 | H34: 267 | J34: 267 | O34: =SUM(J34:M34)-N34 -> 267 | R34: =MONTH(B34) -> 9
